<robot name="UnitreeDog">
  <link name="base_link">
    <visual>
      <origin xyz="0 0 0" rpy="0 0 0"/>
      <geometry>
        <mesh filename="package://uniteedog_description/meshes/trunk.dae" scale="1.0 1.0 1.0"/>
        <!-- <box size="0.5 0.3 0.2"/> length x width x height in meters -->
      </geometry>
       <material name="base_color">
        <color rgba="0.59 0.29 0.0 1.0"/>
      </material>
    </visual>
  </link>
<!-- back hip right -->
  <link name="back_hip_right">
    <visual>
      <origin xyz="0 0 0" rpy="0 3.1416 0"/>
      <geometry>
        <mesh filename="package://uniteedog_description/meshes/hip.dae" scale="1.0 1.0 1.0"/>
      </geometry>
      <material name="base_color">
        <color rgba="0.59 0.29 0.0 1.0"/>
      </material>
    </visual>
  </link>

  <joint name="base_to_back_hip_right" type="revolute">
    <axis xyz="1 0 0"/>
    <parent link="base_link"/>
    <child link="back_hip_right"/>
    <origin xyz="-0.19 -0.05 0" rpy="0 0 0"/>
     <limit lower="-0.6" upper="0.6" effort="10" velocity="0.5"/>
  </joint>

  <!-- back hip left -->
  <link name="back_hip_left">
    <visual>
      <origin xyz="0 0 0" rpy="0 3.1416 0"/>
      <geometry>
        <mesh filename="package://uniteedog_description/meshes/hip.dae" scale="1.0 1.0 1.0"/>
      </geometry>
      <material name="base_color">
        <color rgba="0.59 0.29 0.0 1.0"/>
      </material>
    </visual>
  </link>

  <joint name="base_to_back_hip_left" type="revolute">
    <axis xyz="1 0 0"/>
    <parent link="base_link"/>
    <child link="back_hip_left"/>
    <origin xyz="-0.19 0.05 0" rpy="0 0 0"/>
     <limit lower="-0.6" upper="0.6" effort="10" velocity="0.5"/>
  </joint>

  <!-- front hip right -->
  <link name="front_hip_right">
    <visual>
      <origin xyz="0 0 0" rpy="0 0 0"/>
      <geometry>
        <mesh filename="package://uniteedog_description/meshes/hip.dae" scale="1.0 1.0 1.0"/>
      </geometry>
      <material name="base_color">
        <color rgba="0.59 0.29 0.0 1.0"/>
      </material>
    </visual>
  </link>

  <joint name="base_to_front_hip_right" type="revolute">
    <axis xyz="1 0 0"/>
    <parent link="base_link"/>
    <child link="front_hip_right"/>
    <origin xyz="0.19 -0.05 0" rpy="0 0 0"/>
     <limit lower="-0.6" upper="0.6" effort="10" velocity="0.5"/>
  </joint>


  <!-- front hip left -->
  <link name="front_hip_left">
    <visual>
      <origin xyz="0 0 0" rpy="0 0 0"/>
      <geometry>
        <mesh filename="package://uniteedog_description/meshes/hip.dae" scale="1.0 1.0 1.0"/>
      </geometry>
      <material name="base_color">
        <color rgba="0.59 0.29 0.0 1.0"/>
      </material>
    </visual>
  </link>

  <joint name="base_to_front_hip_left" type="revolute">
    <axis xyz="1 0 0"/>
    <parent link="base_link"/>
    <child link="front_hip_left"/>
    <origin xyz="0.19 0.05 0" rpy="0 0 0"/>
     <limit lower="-0.6" upper="0.6" effort="10" velocity="0.5"/>
  </joint>



<!-- depth Camera -->

  <link name="camera">
    <visual>
      <origin xyz="0 -0.01 0.01" rpy="0.7854 0 0"/>
      <geometry>
        <mesh filename="package://uniteedog_description/meshes/depthCamera.dae" scale="1.0 1.0 1.0"/>
      </geometry>
      <material name="base_color">
        <color rgba="0.9 0.29 0.0 1"/>
      </material>
    </visual>
  </link>

  <joint name="base_to_camera" type="fixed">
    <parent link="base_link"/>
    <child link="camera"/>
    <origin xyz="0.3 0 0" rpy="0 0 0"/>
  </joint>

<!-- ultraSound -->

  <link name="ultraSound">
    <visual>
      <origin xyz="0 0 0.02" rpy="-0.7854 0 0"/>
      <geometry>
        <mesh filename="package://uniteedog_description/meshes/ultraSound.dae" scale="1.0 1.0 1.0"/>
      </geometry>
      <material name="base_color">
        <color rgba="0.9 0.29 0.0 1"/>
      </material>
    </visual>
  </link>

  <joint name="base_to_ultraSound" type="fixed">
    <parent link="camera"/>
    <child link="ultraSound"/>
    <origin xyz="0 0 0" rpy="0 0 0"/>
  </joint>

  <!--  _______________________________  -->


<!--  front leg  -->

    <!-- right front leg -->

  <link name="right_front_leg">
    <visual>
      <origin xyz="0 0 0" rpy=" 0 0.7854 0"/>
      <geometry>
        <mesh filename="package://uniteedog_description/meshes/thigh_mirror.dae" scale="1.0 1.0 1.0"/>
      </geometry>
      <material name="base_color">
        <color rgba="0.59 0.29 0.0 1.0"/>
      </material>
    </visual>
  </link>

  <joint name="base_to_right_front_leg" type="revolute">
    <axis xyz="0 1 0"/>
    <limit lower="-0.52" upper="1.57" effort="10" velocity="0.5"/>
    <parent link="front_hip_right"/>
    <child link="right_front_leg"/>
    <origin xyz="0 -0.08 0 " rpy="0 0 0"/>
  </joint>

<!-- calf front right -->

  <link name="front_calf_right">
    <visual>
      <origin xyz="0 0 0" rpy=" 0 0 0"/>
      <geometry>
        <mesh filename="package://uniteedog_description/meshes/calf.dae" scale="1.0 1.0 1.0"/>
      </geometry>
      <material name="base_color">
        <color rgba="0.59 0.29 0.0 1.0"/>
      </material>
    </visual>
  </link>

  <joint name="right_front_leg_to_calf" type="revolute">
    <axis xyz="0 1 0"/>
    <limit lower="-1.2" upper="0" effort="10" velocity="0.5"/>
    <parent link="right_front_leg"/>
    <child link="front_calf_right"/>
    <origin xyz=" -0.14 0 -0.15 " rpy="0 -0.7854 0"/>
  </joint>  




<!-- front left leg -->

  <link name="left_front_leg">
    <visual>
      <origin xyz="0 0 0" rpy=" 0 0.7854 0"/>
      <geometry>
        <mesh filename="package://uniteedog_description/meshes/thigh.dae" scale="1.0 1.0 1.0"/>
      </geometry>
      <material name="base_color">
        <color rgba="0.59 0.29 0.0 1.0"/>
      </material>
    </visual>
  </link>
 <joint name="base_to_left_front_leg" type="revolute">
    <axis xyz="0 1 0"/>
    <limit lower="-0.52" upper="1.57" effort="10" velocity="0.5"/>
    <parent link="front_hip_left"/>
    <child link="left_front_leg"/>
    <origin xyz="0 0.08 0 " rpy="0 0 0"/>
  </joint>

<!-- calf front left -->

  <link name="front_calf_left">

    <visual>
      <origin xyz="0 0 0" rpy=" 0 0 0"/>
      <geometry>
        <mesh filename="package://uniteedog_description/meshes/calf.dae" scale="1.0 1.0 1.0"/>
      </geometry>
      <material name="base_color">
        <color rgba="0.59 0.29 0.0 1.0"/>
      </material>
    </visual>
  </link>

  <joint name="left_front_leg_to_calf" type="revolute">
    <axis xyz="0 1 0"/>
    <limit lower="-1.2" upper="0" effort="10" velocity="0.5"/>
    <parent link="left_front_leg"/>
    <child link="front_calf_left"/>
    <origin xyz=" -0.14 0 -0.15 " rpy="0 -0.7854 0"/>
  </joint>  


<!--  back leg  -->

    <!-- right back leg -->

  <link name="right_back_leg">
    <visual>
      <origin xyz="0 0 0" rpy=" 0 0.7854 0"/>
      <geometry>
        <mesh filename="package://uniteedog_description/meshes/thigh_mirror.dae" scale="1.0 1.0 1.0"/>
      </geometry>
      <material name="base_color">
        <color rgba="0.59 0.29 0.0 1.0"/>
      </material>
    </visual>
  </link>

  <joint name="hip_to_right_back_leg" type="revolute">
    <axis xyz="0 1 0"/>
    <limit lower="-0.52" upper="1.57" effort="10" velocity="0.5"/>  
    <parent link="back_hip_right"/>
    <child link="right_back_leg"/>
    <origin xyz="0 -0.08 0 " rpy="0 0 0"/>
       <!-- <origin xyz="0 -0.06 0 " rpy="0 0 0"/> -->
  </joint>


    <!-- calf back right -->

  <link name="back_calf_right">

    <visual>
      <origin xyz="0 0 0" rpy=" 0 0 0"/>
      <geometry>
        <mesh filename="package://uniteedog_description/meshes/calf.dae" scale="1.0 1.0 1.0"/>
      </geometry>
      <material name="base_color">
        <color rgba="0.59 0.29 0.0 1.0"/>
      </material>
    </visual>
  </link>

  <joint name="right_back_leg_to_calf" type="revolute">
    <axis xyz="0 1 0"/>
    <limit lower="-1.2" upper="0" effort="10" velocity="0.5"/>
    <parent link="right_back_leg"/>
    <child link="back_calf_right"/>
    <origin xyz=" -0.14 0 -0.15 " rpy="0 -0.7854 0"/>
  </joint>  




    <!-- back left leg -->

  <link name="left_back_leg">
    <visual>
      <origin xyz="0 0 0" rpy=" 0 0.7854 0"/>
      <geometry>
        <mesh filename="package://uniteedog_description/meshes/thigh.dae" scale="1.0 1.0 1.0"/>
      </geometry>
      <material name="base_color">
        <color rgba="0.59 0.29 0.0 1.0"/>
      </material>
    </visual>
  </link>

  <joint name="hip_to_left_back_leg" type="revolute">
    <axis xyz="0 1 0"/>
    <limit lower="-0.52" upper="1.57" effort="10" velocity="0.5"/>
    <parent link="back_hip_left"/>
    <child link="left_back_leg"/>
    <origin xyz="0 0.08 0 " rpy="0 0 0"/>
  </joint>

  <!-- calf back left -->

  <link name="back_calf_left">

    <visual>
      <origin xyz="0 0 0" rpy=" 0 0 0"/>
      <geometry>
        <mesh filename="package://uniteedog_description/meshes/calf.dae" scale="1.0 1.0 1.0"/>
      </geometry>
      <material name="base_color">
        <color rgba="0.59 0.29 0.0 1.0"/>
      </material>
    </visual>
  </link>

  <joint name ="left_back_leg_to_calf" type="revolute">
    <axis xyz="0 1 0"/>
    <limit lower="-1.2" upper="0" effort="10" velocity="0.5"/>
    <parent link="left_back_leg"/>
    <child link="back_calf_left"/>
    <origin xyz=" -0.14 0 -0.15 " rpy="0 -0.7854 0"/>
  </joint>  


  
</robot>
